<?xml version="1.0"?>
<robot name="roarm">

  <material name="yellow"><color rgba="1 0.8 0 1"/></material>
  <material name="grey"><color rgba="0.2 0.2 0.2 1"/></material>

  <link name="world"/>
  <joint name="world_joint" type="fixed">
    <parent link="world"/><child link="base_link"/>
    <origin xyz="0 0 0" rpy="0 0 0"/>
  </joint>

  <link name="base_link">
    <visual>
      <geometry><mesh filename="/home/jos/ros2_ws/src/roarm_description/meshes/base_so101_v2.stl" scale="10.0 10.0 10.0"/></geometry>
      <material name="yellow"/>
    </visual>
    <collision>
      <geometry><mesh filename="/home/jos/ros2_ws/src/roarm_description/meshes/base_so101_v2.stl" scale="10.0 10.0 10.0"/></geometry>
    </collision>
    <inertial>
      <mass value="1.0"/><inertia ixx="0.1" ixy="0" ixz="0" iyy="0.1" iyz="0" izz="0.1"/>
    </inertial>
  </link>

  <joint name="shoulder_pan" type="revolute">
    <parent link="base_link"/><child link="shoulder_link"/>
    <origin xyz="0.388 0 0.624" rpy="0 0 0"/>
    <axis xyz="0 0 1"/>
    <limit lower="-1.91" upper="1.91" effort="10.0" velocity="3.14"/>
  </joint>

  <link name="shoulder_link">
    <visual>
      <origin xyz="-0.3 0 -0.41" rpy="0 0 3.14159"/>
      <geometry><mesh filename="/home/jos/ros2_ws/src/roarm_description/meshes/sts3215_03a_v1.stl" scale="10.0 10.0 10.0"/></geometry>
      <material name="grey"/>
    </visual>
    <visual>
      <origin xyz="-0.67 0 0.15" rpy="0 0 0"/>
      <geometry><mesh filename="/home/jos/ros2_ws/src/roarm_description/meshes/motor_holder_so101_base_v1.stl" scale="10.0 10.0 10.0"/></geometry>
      <material name="yellow"/>
    </visual>
    <inertial><mass value="0.5"/><inertia ixx="0.05" ixy="0" ixz="0" iyy="0.05" iyz="0" izz="0.05"/></inertial>
  </link>

  <joint name="shoulder_lift" type="revolute">
    <parent link="shoulder_link"/><child link="upper_arm_link"/>
    <origin xyz="-0.3 -0.18 -0.54" rpy="1.5708 -1.5708 0"/>
    <axis xyz="0 0 1"/>
    <limit lower="-1.74" upper="1.74" effort="10.0" velocity="3.14"/>
  </joint>

  <link name="upper_arm_link">
    <visual>
      <origin xyz="-0.65 0.12 0.18" rpy="0 1.5708 0"/>
      <geometry><mesh filename="/home/jos/ros2_ws/src/roarm_description/meshes/upper_arm_so101_v1.stl" scale="10.0 10.0 10.0"/></geometry>
      <material name="yellow"/>
    </visual>
    <inertial><mass value="0.4"/><inertia ixx="0.04" ixy="0" ixz="0" iyy="0.04" iyz="0" izz="0.04"/></inertial>
  </link>

  <joint name="elbow_flex" type="revolute">
    <parent link="upper_arm_link"/><child link="lower_arm_link"/>
    <origin xyz="-1.12 -0.28 0" rpy="0 0 0"/>
    <axis xyz="0 0 1"/>
    <limit lower="-1.69" upper="1.69" effort="10.0" velocity="3.14"/>
  </joint>

  <link name="lower_arm_link">
    <visual>
      <origin xyz="-0.64 -0.32 0.18" rpy="0 1.5708 0"/>
      <geometry><mesh filename="/home/jos/ros2_ws/src/roarm_description/meshes/under_arm_so101_v1.stl" scale="10.0 10.0 10.0"/></geometry>
      <material name="yellow"/>
    </visual>
    <inertial><mass value="0.3"/><inertia ixx="0.03" ixy="0" ixz="0" iyy="0.03" iyz="0" izz="0.03"/></inertial>
  </link>

  <joint name="wrist_flex" type="revolute">
    <parent link="lower_arm_link"/><child link="wrist_link"/>
    <origin xyz="-1.34 0.05 0" rpy="0 0 0"/>
    <axis xyz="0 0 1"/>
    <limit lower="-1.65" upper="1.65" effort="10.0" velocity="3.14"/>
  </joint>

  <link name="wrist_link">
    <visual>
      <origin xyz="0 -0.28 0.18" rpy="1.5708 0 0"/>
      <geometry><mesh filename="/home/jos/ros2_ws/src/roarm_description/meshes/wrist_roll_pitch_so101_v2.stl" scale="10.0 10.0 10.0"/></geometry>
      <material name="yellow"/>
    </visual>
    <inertial><mass value="0.2"/><inertia ixx="0.02" ixy="0" ixz="0" iyy="0.02" iyz="0" izz="0.02"/></inertial>
  </link>

  <joint name="wrist_roll" type="revolute">
    <parent link="wrist_link"/><child link="gripper_base_link"/>
    <origin xyz="0 -0.61 0.18" rpy="-1.5708 0 0"/>
    <axis xyz="0 0 1"/>
    <limit lower="-2.74" upper="2.84" effort="10.0" velocity="3.14"/>
  </joint>

  <link name="gripper_base_link">
    <visual>
      <geometry><mesh filename="/home/jos/ros2_ws/src/roarm_description/meshes/wrist_roll_follower_so101_v1.stl" scale="10.0 10.0 10.0"/></geometry>
      <material name="yellow"/>
    </visual>
    <inertial><mass value="0.1"/><inertia ixx="0.01" ixy="0" ixz="0" iyy="0.01" iyz="0" izz="0.01"/></inertial>
  </link>

  <joint name="gripper" type="revolute">
    <parent link="gripper_base_link"/><child link="jaw_link"/>
    <origin xyz="0.2 0.18 -0.23" rpy="0 0 0"/>
    <axis xyz="0 0 1"/>
    <limit lower="-0.17" upper="1.74" effort="5.0" velocity="1.0"/>
  </joint>

  <link name="jaw_link">
    <visual>
      <origin xyz="0 0 0.18" rpy="0 0 0"/>
      <geometry><mesh filename="/home/jos/ros2_ws/src/roarm_description/meshes/moving_jaw_so101_v1.stl" scale="10.0 10.0 10.0"/></geometry>
      <material name="yellow"/>
    </visual>
    <inertial><mass value="0.05"/><inertia ixx="0.005" ixy="0" ixz="0" iyy="0.005" iyz="0" izz="0.005"/></inertial>
  </link>

</robot>
